<?xml version="1.0" encoding="utf-8"?>
<!-- This URDF was automatically created by SolidWorks to URDF Exporter! Originally created by Stephen Brawner (brawner@gmail.com) 
     Commit Version: 1.6.0-1-g15f4949  Build Version: 1.6.7594.29634
     For more information, please see http://wiki.ros.org/sw_urdf_exporter -->
<robot
  name="linkerhand_l21_left">
  <link
    name="hand_base_link">
    <inertial>
      <origin
        xyz="0.027711 0.0087195 0.076284"
        rpy="0 0 0" />
      <mass
        value="1.5785E-07" />
      <inertia
        ixx="4.2149E-15"
        ixy="2.3826E-15"
        ixz="7.6961E-16"
        iyy="5.6185E-14"
        iyz="-8.7449E-16"
        izz="5.3828E-14" />
    </inertial>
    <visual>
      <origin
        xyz="0 0 0"
        rpy="0 0 0" />
      <geometry>
        <mesh
          filename="meshes/hand_base_link.STL" />
      </geometry>
      <material
        name="">
        <color
          rgba="1 1 1 1" />
      </material>
    </visual>
    <collision>
      <origin
        xyz="0 0 0"
        rpy="0 0 0" />
      <geometry>
        <mesh
          filename="meshes/hand_base_link.STL" />
      </geometry>
    </collision>
  </link>
  <link
    name="index_metacarpals">
    <inertial>
      <origin
        xyz="0.0053256 0.0026647 -0.015279"
        rpy="0 0 0" />
      <mass
        value="0.00041989" />
      <inertia
        ixx="1.2323E-08"
        ixy="-1.6725E-11"
        ixz="4.7753E-10"
        iyy="5.5651E-09"
        iyz="7.8846E-11"
        izz="7.5215E-09" />
    </inertial>
    <visual>
      <origin
        xyz="0 0 0"
        rpy="0 0 0" />
      <geometry>
        <mesh
          filename="meshes/index_metacarpals.STL" />
      </geometry>
      <material
        name="">
        <color
          rgba="1 1 1 1" />
      </material>
    </visual>
    <collision>
      <origin
        xyz="0 0 0"
        rpy="0 0 0" />
      <geometry>
        <mesh
          filename="meshes/index_metacarpals.STL" />
      </geometry>
    </collision>
  </link>
  <joint
    name="index_mcp_roll"
    type="revolute">
    <origin
      xyz="0.0059834 -0.032908 0.13338"
      rpy="-0.0056645 0 0" />
    <parent
      link="hand_base_link" />
    <child
      link="index_metacarpals" />
    <axis
      xyz="1 0 0" />
    <limit
      lower="0"
      upper="0.18"
      effort="100"
      velocity="1" />
  </joint>
  <link
    name="index_proximal">
    <inertial>
      <origin
        xyz="0.00827300262446084 0.0206946536676659 -0.0594111984214959"
        rpy="0 0 0" />
      <mass
        value="0.00310189617600549" />
      <inertia
        ixx="6.94827809852598E-06"
        ixy="-7.30360932101661E-07"
        ixz="-3.50357323679268E-07"
        iyy="3.62827463376843E-06"
        iyz="1.32196221507174E-06"
        izz="4.38448341497944E-06" />
    </inertial>
    <visual>
      <origin
        xyz="0 0 0"
        rpy="0 0 0" />
      <geometry>
        <mesh
          filename="meshes/index_proximal.STL" />
      </geometry>
      <material
        name="">
        <color
          rgba="1 1 1 1" />
      </material>
    </visual>
    <collision>
      <origin
        xyz="0 0 0"
        rpy="0 0 0" />
      <geometry>
        <mesh
          filename="meshes/index_proximal.STL" />
      </geometry>
    </collision>
  </link>
  <joint
    name="index_mcp_pitch"
    type="revolute">
    <origin
      xyz="0.002358 -0.00022359 0.018075"
      rpy="0 0 0" />
    <parent
      link="index_metacarpals" />
    <child
      link="index_proximal" />
    <axis
      xyz="0 1 0" />
    <limit
      lower="0"
      upper="1.57"
      effort="100"
      velocity="1" />
  </joint>
  <link
    name="index_middle">
    <inertial>
      <origin
        xyz="0.0084310026295624 0.0206979632977038 -0.103411198516156"
        rpy="0 0 0" />
      <mass
        value="0.00310189617600549" />
      <inertia
        ixx="6.94827809845368E-06"
        ixy="-7.303609322448E-07"
        ixz="-3.50357323896878E-07"
        iyy="3.62827463378371E-06"
        iyz="1.32196221500947E-06"
        izz="4.38448341503647E-06" />
    </inertial>
    <visual>
      <origin
        xyz="0 0 0"
        rpy="0 0 0" />
      <geometry>
        <mesh
          filename="meshes/index_middle.STL" />
      </geometry>
      <material
        name="">
        <color
          rgba="1 1 1 1" />
      </material>
    </visual>
    <collision>
      <origin
        xyz="0 0 0"
        rpy="0 0 0" />
      <geometry>
        <mesh
          filename="meshes/index_middle.STL" />
      </geometry>
    </collision>
  </link>
  <joint
    name="index_pip"
    type="revolute">
    <origin
      xyz="-0.000158 0 0.044"
      rpy="0 0 0" />
    <parent
      link="index_proximal" />
    <child
      link="index_middle" />
    <axis
      xyz="0 1 0" />
    <limit
      lower="0"
      upper="1.57"
      effort="100"
      velocity="1" />
  </joint>
  <link
    name="middle_metacarpals">
    <inertial>
      <origin
        xyz="0.00809602648732219 0.000967328077867452 -0.0158492205753797"
        rpy="0 0 0" />
      <mass
        value="0.000489979599946496" />
      <inertia
        ixx="1.70467250478746E-08"
        ixy="-2.49125202430984E-11"
        ixz="4.77383630918998E-10"
        iyy="6.25256440139051E-09"
        iyz="-7.03912454501969E-11"
        izz="1.16457113735344E-08" />
    </inertial>
    <visual>
      <origin
        xyz="0 0 0"
        rpy="0 0 0" />
      <geometry>
        <mesh
          filename="meshes/middle_metacarpals.STL" />
      </geometry>
      <material
        name="">
        <color
          rgba="1 1 1 1" />
      </material>
    </visual>
    <collision>
      <origin
        xyz="0 0 0"
        rpy="0 0 0" />
      <geometry>
        <mesh
          filename="meshes/middle_metacarpals.STL" />
      </geometry>
    </collision>
  </link>
  <joint
    name="middle_mcp_roll"
    type="revolute">
    <origin
      xyz="0.0059834 -0.010766 0.14075"
      rpy="-0.0056645 0 0" />
    <parent
      link="hand_base_link" />
    <child
      link="middle_metacarpals" />
    <axis
      xyz="1 0 0" />
    <limit
      lower="-0.18"
      upper="0.18"
      effort="100"
      velocity="1" />
  </joint>
  <link
    name="middle_proximal">
    <inertial>
      <origin
        xyz="0.00827258573746481 -0.00140534633098602 -0.0669111984292696"
        rpy="0 0 0" />
      <mass
        value="0.00310189617600549" />
      <inertia
        ixx="6.94827809852754E-06"
        ixy="-7.30360932098109E-07"
        ixz="-3.50357323677855E-07"
        iyy="3.62827463376687E-06"
        iyz="1.32196221507212E-06"
        izz="4.38448341497944E-06" />
    </inertial>
    <visual>
      <origin
        xyz="0 0 0"
        rpy="0 0 0" />
      <geometry>
        <mesh
          filename="meshes/middle_proximal.STL" />
      </geometry>
      <material
        name="">
        <color
          rgba="1 1 1 1" />
      </material>
    </visual>
    <collision>
      <origin
        xyz="0 0 0"
        rpy="0 0 0" />
      <geometry>
        <mesh
          filename="meshes/middle_proximal.STL" />
      </geometry>
    </collision>
  </link>
  <joint
    name="middle_mcp_pitch"
    type="revolute">
    <origin
      xyz="0.0023586 -0.0002236 0.018075"
      rpy="0 0 0" />
    <parent
      link="middle_metacarpals" />
    <child
      link="middle_proximal" />
    <axis
      xyz="0 1 0" />
    <limit
      lower="0"
      upper="1.57"
      effort="100"
      velocity="1" />
  </joint>
  <link
    name="middle_middle">
    <inertial>
      <origin
        xyz="0.00782855721567354 -0.00141464740089148 -0.110909241690445"
        rpy="0 0 0" />
      <mass
        value="0.00310189617600549" />
      <inertia
        ixx="6.94827809845522E-06"
        ixy="-7.30360932241238E-07"
        ixz="-3.50357323895577E-07"
        iyy="3.62827463378255E-06"
        iyz="1.32196221500995E-06"
        izz="4.38448341503608E-06" />
    </inertial>
    <visual>
      <origin
        xyz="0 0 0"
        rpy="0 0 0" />
      <geometry>
        <mesh
          filename="meshes/middle_middle.STL" />
      </geometry>
      <material
        name="">
        <color
          rgba="1 1 1 1" />
      </material>
    </visual>
    <collision>
      <origin
        xyz="0 0 0"
        rpy="0 0 0" />
      <geometry>
        <mesh
          filename="meshes/middle_middle.STL" />
      </geometry>
    </collision>
  </link>
  <joint
    name="middle_pip"
    type="revolute">
    <origin
      xyz="0.00044403 0 0.043998"
      rpy="0 0 0" />
    <parent
      link="middle_proximal" />
    <child
      link="middle_middle" />
    <axis
      xyz="0 1 0" />
    <limit
      lower="0"
      upper="1.57"
      effort="100"
      velocity="1" />
  </joint>
  <link
    name="ring_metacarpals">
    <inertial>
      <origin
        xyz="0.00568290695019562 0.00100546703192139 -0.0157134930728382"
        rpy="0 0 0" />
      <mass
        value="0.000471375650794161" />
      <inertia
        ixx="1.63734413760856E-08"
        ixy="-2.48713921673637E-11"
        ixz="4.77563154016997E-10"
        iyy="6.04018250418069E-09"
        iyz="-7.04143076046795E-11"
        izz="1.11386555110261E-08" />
    </inertial>
    <visual>
      <origin
        xyz="0 0 0"
        rpy="0 0 0" />
      <geometry>
        <mesh
          filename="meshes/ring_metacarpals.STL" />
      </geometry>
      <material
        name="">
        <color
          rgba="1 1 1 1" />
      </material>
    </visual>
    <collision>
      <origin
        xyz="0 0 0"
        rpy="0 0 0" />
      <geometry>
        <mesh
          filename="meshes/ring_metacarpals.STL" />
      </geometry>
    </collision>
  </link>
  <joint
    name="ring_mcp_roll"
    type="revolute">
    <origin
      xyz="0.0059834 0.010791 0.13313"
      rpy="-0.0056645 0 0" />
    <parent
      link="hand_base_link" />
    <child
      link="ring_metacarpals" />
    <axis
      xyz="1 0 0" />
    <limit
      lower="-0.18"
      upper="0.18"
      effort="100"
      velocity="1" />
  </joint>
  <link
    name="ring_proximal">
    <inertial>
      <origin
        xyz="0.00827216885200012 -0.0230051873236801 -0.0594111923224606"
        rpy="0 0 0" />
      <mass
        value="0.00310189617600549" />
      <inertia
        ixx="6.94827809852909E-06"
        ixy="-7.30360932087472E-07"
        ixz="-3.5035732369126E-07"
        iyy="3.62827463381894E-06"
        iyz="1.32196221508782E-06"
        izz="4.38448341492582E-06" />
    </inertial>
    <visual>
      <origin
        xyz="0 0 0"
        rpy="0 0 0" />
      <geometry>
        <mesh
          filename="meshes/ring_proximal.STL" />
      </geometry>
      <material
        name="">
        <color
          rgba="1 1 1 1" />
      </material>
    </visual>
    <collision>
      <origin
        xyz="0 0 0"
        rpy="0 0 0" />
      <geometry>
        <mesh
          filename="meshes/ring_proximal.STL" />
      </geometry>
    </collision>
  </link>
  <joint
    name="ring_mcp_pitch"
    type="revolute">
    <origin
      xyz="0.0023592 -0.0002236 0.018075"
      rpy="0 0 0" />
    <parent
      link="ring_metacarpals" />
    <child
      link="ring_proximal" />
    <axis
      xyz="0 1 0" />
    <limit
      lower="0"
      upper="1.57"
      effort="100"
      velocity="1" />
  </joint>
  <link
    name="ring_middle">
    <inertial>
      <origin
        xyz="0.00843016885556375 -0.0230018776948784 -0.103411192401526"
        rpy="0 0 0" />
      <mass
        value="0.00310189617600549" />
      <inertia
        ixx="6.94827809845368E-06"
        ixy="-7.30360932244799E-07"
        ixz="-3.50357323896877E-07"
        iyy="3.62827463378371E-06"
        iyz="1.32196221500947E-06"
        izz="4.38448341503647E-06" />
    </inertial>
    <visual>
      <origin
        xyz="0 0 0"
        rpy="0 0 0" />
      <geometry>
        <mesh
          filename="meshes/ring_middle.STL" />
      </geometry>
      <material
        name="">
        <color
          rgba="1 1 1 1" />
      </material>
    </visual>
    <collision>
      <origin
        xyz="0 0 0"
        rpy="0 0 0" />
      <geometry>
        <mesh
          filename="meshes/ring_middle.STL" />
      </geometry>
    </collision>
  </link>
  <joint
    name="ring_pip"
    type="revolute">
    <origin
      xyz="-0.000158 0 0.044"
      rpy="0 0 0" />
    <parent
      link="ring_proximal" />
    <child
      link="ring_middle" />
    <axis
      xyz="0 1 0" />
    <limit
      lower="0"
      upper="1.57"
      effort="100"
      velocity="1" />
  </joint>
  <link
    name="pinky_metacarpals">
    <inertial>
      <origin
        xyz="0.00770791352923251 -0.000457498596015515 -0.0154299306024431"
        rpy="0 0 0" />
      <mass
        value="0.000436259943198178" />
      <inertia
        ixx="1.28165947659315E-08"
        ixy="-3.35211054873818E-11"
        ixz="4.77347680805677E-10"
        iyy="5.75479262594543E-09"
        iyz="-2.2806555796648E-10"
        izz="7.86609440553176E-09" />
    </inertial>
    <visual>
      <origin
        xyz="0 0 0"
        rpy="0 0 0" />
      <geometry>
        <mesh
          filename="meshes/pinky_metacarpals.STL" />
      </geometry>
      <material
        name="">
        <color
          rgba="1 1 1 1" />
      </material>
    </visual>
    <collision>
      <origin
        xyz="0 0 0"
        rpy="0 0 0" />
      <geometry>
        <mesh
          filename="meshes/pinky_metacarpals.STL" />
      </geometry>
    </collision>
  </link>
  <joint
    name="pinky_mcp_roll"
    type="revolute">
    <origin
      xyz="0.0059834 0.032806 0.11807"
      rpy="-0.0056645 0 0" />
    <parent
      link="hand_base_link" />
    <child
      link="pinky_metacarpals" />
    <axis
      xyz="-1 0 0" />
    <limit
      lower="0"
      upper="0.18"
      effort="100"
      velocity="1" />
  </joint>
  <link
    name="pinky_proximal">
    <inertial>
      <origin
        xyz="0.00827175196559392 -0.0451053470230371 -0.0444732534937471"
        rpy="0 0 0" />
      <mass
        value="0.00310189617600549" />
      <inertia
        ixx="6.94827809852754E-06"
        ixy="-7.30360932090995E-07"
        ixz="-3.50357323692668E-07"
        iyy="3.6282746338205E-06"
        iyz="1.32196221508746E-06"
        izz="4.3844834149258E-06" />
    </inertial>
    <visual>
      <origin
        xyz="0 0 0"
        rpy="0 0 0" />
      <geometry>
        <mesh
          filename="meshes/pinky_proximal.STL" />
      </geometry>
      <material
        name="">
        <color
          rgba="1 1 1 1" />
      </material>
    </visual>
    <collision>
      <origin
        xyz="0 0 0"
        rpy="0 0 0" />
      <geometry>
        <mesh
          filename="meshes/pinky_proximal.STL" />
      </geometry>
    </collision>
  </link>
  <joint
    name="pinky_mcp_pitch"
    type="revolute">
    <origin
      xyz="0.0023598 -0.0002236 0.018075"
      rpy="0 0 0" />
    <parent
      link="pinky_metacarpals" />
    <child
      link="pinky_proximal" />
    <axis
      xyz="0 1 0" />
    <limit
      lower="0"
      upper="1.57"
      effort="100"
      velocity="1" />
  </joint>
  <link
    name="pinky_middle">
    <inertial>
      <origin
        xyz="0.00842975196858262 -0.0451020373939276 -0.0884732535762509"
        rpy="0 0 0" />
      <mass
        value="0.00310189617600549" />
      <inertia
        ixx="6.94827809845368E-06"
        ixy="-7.30360932244799E-07"
        ixz="-3.50357323896877E-07"
        iyy="3.62827463378371E-06"
        iyz="1.32196221500947E-06"
        izz="4.38448341503647E-06" />
    </inertial>
    <visual>
      <origin
        xyz="0 0 0"
        rpy="0 0 0" />
      <geometry>
        <mesh
          filename="meshes/pinky_middle.STL" />
      </geometry>
      <material
        name="">
        <color
          rgba="1 1 1 1" />
      </material>
    </visual>
    <collision>
      <origin
        xyz="0 0 0"
        rpy="0 0 0" />
      <geometry>
        <mesh
          filename="meshes/pinky_middle.STL" />
      </geometry>
    </collision>
  </link>
  <joint
    name="pinky_pip"
    type="revolute">
    <origin
      xyz="-0.000158 0 0.044"
      rpy="0 0 0" />
    <parent
      link="pinky_proximal" />
    <child
      link="pinky_middle" />
    <axis
      xyz="0 1 0" />
    <limit
      lower="0"
      upper="1.57"
      effort="100"
      velocity="1" />
  </joint>
  <link
    name="thumb_metacarpals_base1">
    <inertial>
      <origin
        xyz="-0.00825004343050429 0.00549999923187541 -0.0318466649750455"
        rpy="0 0 0" />
      <mass
        value="0.000312218028756713" />
      <inertia
        ixx="1.10352320577714E-08"
        ixy="1.51530066694108E-15"
        ixz="2.24883986234982E-17"
        iyy="1.03390792483618E-09"
        iyz="-9.75961461153178E-16"
        izz="1.09679882723771E-08" />
    </inertial>
    <visual>
      <origin
        xyz="0 0 0"
        rpy="0 0 0" />
      <geometry>
        <mesh
          filename="meshes/thumb_metacarpals_base1.STL" />
      </geometry>
      <material
        name="">
        <color
          rgba="1 1 1 1" />
      </material>
    </visual>
    <collision>
      <origin
        xyz="0 0 0"
        rpy="0 0 0" />
      <geometry>
        <mesh
          filename="meshes/thumb_metacarpals_base1.STL" />
      </geometry>
    </collision>
  </link>
  <joint
    name="thumb_cmc_roll"
    type="revolute">
    <origin
      xyz="0.002384 -0.002009 0.071277"
      rpy="-0.0056645 0 0" />
    <parent
      link="hand_base_link" />
    <child
      link="thumb_metacarpals_base1" />
    <axis
      xyz="-1 0 0" />
    <limit
      lower="-0.6"
      upper="0.6"
      effort="100"
      velocity="1" />
  </joint>
  <link
    name="thumb_metacarpals_base2">
    <inertial>
      <origin
        xyz="0.000318715623666761 -0.00718337748979808 0.00156863530629658"
        rpy="0 0 0" />
      <mass
        value="0.000612301579502896" />
      <inertia
        ixx="1.22173338759595E-08"
        ixy="-4.04328465962207E-10"
        ixz="-7.85625856505701E-10"
        iyy="2.54580972505203E-08"
        iyz="-8.83243860874543E-11"
        izz="1.4128984259509E-08" />
    </inertial>
    <visual>
      <origin
        xyz="0 0 0"
        rpy="0 0 0" />
      <geometry>
        <mesh
          filename="meshes/thumb_metacarpals_base2.STL" />
      </geometry>
      <material
        name="">
        <color
          rgba="1 1 1 1" />
      </material>
    </visual>
    <collision>
      <origin
        xyz="0 0 0"
        rpy="0 0 0" />
      <geometry>
        <mesh
          filename="meshes/thumb_metacarpals_base2.STL" />
      </geometry>
    </collision>
  </link>
  <joint
    name="thumb_cmc_yaw"
    type="revolute">
    <origin
      xyz="0.02725 -0.008383 -0.0024"
      rpy="0 0 0.00011487" />
    <parent
      link="thumb_metacarpals_base1" />
    <child
      link="thumb_metacarpals_base2" />
    <axis
      xyz="0 0 1" />
    <limit
      lower="0"
      upper="1.6"
      effort="100"
      velocity="1" />
  </joint>
  <link
    name="thumb_metacarpals">
    <inertial>
      <origin
        xyz="-0.0142748361598372 0.00532040432196624 0.00526552927499724"
        rpy="0 0 0" />
      <mass
        value="8.32841435663313E-05" />
      <inertia
        ixx="8.35185788663659E-10"
        ixy="-2.55411350654767E-15"
        ixz="1.71799639980897E-13"
        iyy="7.2277546470753E-10"
        iyz="-2.53341629842261E-13"
        izz="1.98745918720938E-10" />
    </inertial>
    <visual>
      <origin
        xyz="0 0 0"
        rpy="0 0 0" />
      <geometry>
        <mesh
          filename="meshes/thumb_metacarpals.STL" />
      </geometry>
      <material
        name="">
        <color
          rgba="1 1 1 1" />
      </material>
    </visual>
    <collision>
      <origin
        xyz="0 0 0"
        rpy="0 0 0" />
      <geometry>
        <mesh
          filename="meshes/thumb_metacarpals.STL" />
      </geometry>
    </collision>
  </link>
  <joint
    name="thumb_cmc_pitch"
    type="revolute">
    <origin
      xyz="0.0063626 -0.01451 0.0040125"
      rpy="3.1416 -1.5438 -1.6" />
    <parent
      link="thumb_metacarpals_base2" />
    <child
      link="thumb_metacarpals" />
    <axis
      xyz="0 1 0" />
    <limit
      lower="0"
      upper="1"
      effort="100"
      velocity="1" />
  </joint>
  <link
    name="thumb_proximal">
    <inertial>
      <origin
        xyz="-0.0184739779964296 -0.0002000000495994 0.0462329062867987"
        rpy="0 0 0" />
      <mass
        value="0.000276348923230502" />
      <inertia
        ixx="1.87209908989575E-09"
        ixy="-2.063629189239E-20"
        ixz="1.07714355532501E-10"
        iyy="1.86535523180589E-09"
        iyz="3.29607314612381E-19"
        izz="3.58579214390665E-09" />
    </inertial>
    <visual>
      <origin
        xyz="0 0 0"
        rpy="0 0 0" />
      <geometry>
        <mesh
          filename="meshes/thumb_proximal.STL" />
      </geometry>
      <material
        name="">
        <color
          rgba="1 1 1 1" />
      </material>
    </visual>
    <collision>
      <origin
        xyz="0 0 0"
        rpy="0 0 0" />
      <geometry>
        <mesh
          filename="meshes/thumb_proximal.STL" />
      </geometry>
    </collision>
  </link>
  <joint
    name="thumb_mcp"
    type="revolute">
    <origin
      xyz="-0.0039464 0 0.034242"
      rpy="0 0.026973 0" />
    <parent
      link="thumb_metacarpals" />
    <child
      link="thumb_proximal" />
    <axis
      xyz="0 1 0" />
    <limit
      lower="0"
      upper="1.57"
      effort="100"
      velocity="1" />
  </joint>
  <link
    name="thumb_distal">
    <inertial>
      <origin
        xyz="0.0178854812171841 0.019727222652815 -0.0945726187383213"
        rpy="0 0 0" />
      <mass
        value="0.00310189617600549" />
      <inertia
        ixx="4.69661957827236E-06"
        ixy="2.83090317743629E-07"
        ixz="-1.18320195426291E-06"
        iyy="6.90308365393113E-06"
        iyz="-8.67349614751342E-07"
        izz="3.36133291507035E-06" />
    </inertial>
    <visual>
      <origin
        xyz="0 0 0"
        rpy="0 0 0" />
      <geometry>
        <mesh
          filename="meshes/thumb_distal.STL" />
      </geometry>
      <material
        name="">
        <color
          rgba="1 1 1 1" />
      </material>
    </visual>
    <collision>
      <origin
        xyz="0 0 0"
        rpy="0 0 0" />
      <geometry>
        <mesh
          filename="meshes/thumb_distal.STL" />
      </geometry>
    </collision>
  </link>
  <joint
    name="thumb_ip"
    type="revolute">
    <origin
      xyz="-0.0056449 0 0.045952"
      rpy="0 -0.12449 0" />
    <parent
      link="thumb_proximal" />
    <child
      link="thumb_distal" />
    <axis
      xyz="0 1 0" />
    <limit
      lower="0"
      upper="1.57"
      effort="100"
      velocity="1" />
  </joint>
</robot>